Workbook

Sheet 기본입력
A1: 7410E 부문감사인 그룹감사지침서(영문)의 기본입력사항
A3: 기본입력항목 | B3: 기본입력내용(국문) | C3: 기본입력내용(영문)
A4: 지배기업명(name of parent entity) | B4: ABC주식회사 | C4: ABC Compony
A5: 지배기업 회계연도 개시일 | B5: 43101
A6: 지배기업 회계연도 종료일 | B6: 43465
A7: 부문감사인명 | B7: XX회계법인 | C7: XX accounting corporation
A8: 감사지침서일 | B8: 43342
A9: 부문명(name of component) | B9: 가나다주식회사 | C9: GANADA compony
A10: 부문 회계연도 개시일 | B10: 43101
A11: 부문 회계연도 종료일 | B11: 43465
A12: 해당부문 전체중요성(백만원) | B12: 400
A13: 해당부문 경미한왜곡표시사항에 대한 기준치(백만원) | B13: 5
A14: 후속사건검토요청일 | B14: 43524
A16: * 본 시트는 기본입력사항을 입력하는 시트로서 출력하여 조서화하는 시트가 아닙니다.

Sheet 7410E
A6: 7410E Group Audit Letter of Instruction
A8: Parent Entity Name: | C8: =기본입력!C4 -> ABC Compony
A9: Fiscal Year : | C9: ="the yeat ended "&TEXT(기본입력!B6,"mmm d, yyyy") -> the yeat ended Dec 31, 2018
A12: ="Dear "&기본입력!C7&":" -> Dear XX accounting corporation:
A13: =TEXT(기본입력!B8,"mmm d,yyyy") -> Aug 30,2018
A15: ="We are pleased to inform you that we would like your firm to participate in the audit of "&기본입력!C4&" for the year ending "&TEXT(기본입력!B5,"mmm d,yyyy")&". The nature and extent of your participation is explained in the group audit instructions attached to this letter. Please make the necessary arrangements to perform this work. " -> We are pleased to inform you that we would like your firm to participate in the audit of ABC Compony for the year ending Jan 1,2018. The nature and extent of your participation is explained in the group audit instructions attached to this letter. Please make the necessary arrangements to perform this work.
A17: ="We require you to perform the specified work on the financial information of "&기본입력!C9&" for the year ended "&TEXT(기본입력!B11,"mmm d,yyyy")&" by complying with our instructions. The work you will perform on your component will form part of the audit of the group financial statements of "&기본입력!C4 -> We require you to perform the specified work on the financial information of GANADA compony for the year ended Dec 31,2018 by complying with our instructions. The work you will perform on your component will form part of the audit of the group financial statements of ABC Compony
A19: Please refer to the attached group audit instructions and the related appendices for details on the nature, timing and extent of the work requested of your office. We would be grateful if you provide us with responses as requested in this letter on a timely basis.
A21: During planning, performance or completion of the audit, please communicate with us immediately if:
A23: Instructions are not fully understood,
A24: Timing of the work creates an irresolvable problem,
A25: It is necessary to vary procedures from those specified,
A26: You become aware of events, transactions that may have a significant impact on the component or other members of the affiliated group (e.g., instances of fraud, significant changes to the level of control reliance, illegal acts, etc).
A27: Services have been performed without the appropriate pre-approvals or consideration of the independence matters discussed in the group audit instructions,
A28: Circumstances arise that may result in an opinion other than one of those presented in the appendices (including a modification for a scope limitation or qualification),
A30: Please contact the Group Engagement Team before any additional procedures on intercompany are performed locally.
A31: Name | B31: Telephone | C31: Fax number | D31: E-mail
A34: Address
A37: ="Please do not hesitate to contact us should you have any question concerning these instructions or any other matter concerning the audit of "&기본입력!C4&"." -> Please do not hesitate to contact us should you have any question concerning these instructions or any other matter concerning the audit of ABC Compony.
A39: Yours faithfully,
G42: YY Accounting Corporation
G43: [Name of Group Engagement Leader]
A45: General Instruction
A47: =CONCATENATE("YY accounting corporaion has been engaged to audit the group financial statements of ",기본입력!C4," as of and for the year ending ",TEXT(기본입력!B6,"mmm d,yyyy"),", in accordance with [indicate applicable financial reporting framework e.g. IFRS as issued by the International Accounting Standards Board].") -> YY accounting corporaion has been engaged to audit the group financial statements of ABC Compony as of and for the year ending Dec 31,2018, in accordance with [indicate applicable financial reporting framework e.g. IFRS as issued by the International Accounting Standards Board].
A48: The group audit instructions set forth the procedures that we, the group engagement team, require you, the component auditor, to perform on the financial information of the component for which you are responsible.
A50: (1) Group Information
A51: Group Name | D51: =기본입력!C4 -> ABC Compony
A52: Business operations
A53: Names of related parties
A57: (Others: Significant change in business compared with prior year, etc.)
A62: (2) Audit scoping
A63: Component name | D63: =기본입력!C9 -> GANADA compony
A64: Financial Reporting Framework | D64: □ K-IFRS □ K-GAAP □ Group Accounting Manual □ Others( )
A65: Auditing Standards | D65: □ K-GAAS □ Others( )
A66: Fiscal Year | D66: ="from "&TEXT(기본입력!B10,"mmm d,yyyy")&" to "&TEXT(기본입력!B11,"mmm d,yyyy") -> from Jan 1,2018 to Dec 31,2018
A67: Scope | D67: Audit (*1)
A68: Scope detailed | D68: □ An audit of the reporting package for the group □ An statutory audit of the financial information of the component □ Others( )
A70: Materiality(Korean Won in millions) | D70: Overall Materiality | H70: =기본입력!B12 -> 400
D71: Amount below which misstatements would be clearly trivial | H71: =기본입력!B13 -> 5
A72: Subsequnt Events Review date | D72: =TEXT(기본입력!B14,"mmm d,yyyy") -> Feb 28,2019
...
