Workbook
Name _: #N/A
Name ___EPS2: #REF!
Name __DAT14: #REF!
Name __DemandLoad: TRUE
Name __EPS2: #REF!
Name __G79999: #REF!
Name __G99998: [3]임대!#REF!
Name __G99999: #REF!
Name __N84081: #REF!
Name __N94081: #REF!
Name _10: #N/A
Name _100P4_: #N/A
Name _101P5_: #N/A
Name _102P6_: #N/A
Name _10320: #N/A
Name _103P7_: #N/A
Name _10B00__27__.DATABASEUPLOAD: #N/A
Name _10T1: #N/A
Name _10T2: #N/A
Name _118y23_: '[2]2500'!#REF!
Name _11B00__3__.DATABASEUPLOAD: #N/A
Name _12_31_97: #N/A
Name _12_31_98: #N/A
Name _12_31_99: #N/A
Name _12B00__4__.DATABASEUPLOAD: #N/A
Name _13B00__40__.DATABASEUPLOAD: #N/A
Name _14B00__44__.DATABASEUPLOAD: #N/A
Name _15A: #N/A
Name _15B00__45__.DATABASEUPLOAD: #N/A
Name _16B00__46__.DATABASEUPLOAD: #N/A
Name _17B00__48__.DATABASEUPLOAD: #N/A
Name _18B00__5__.DATABASEUPLOAD: #N/A
Name _1999_01_29: #N/A
Name _19B00__50__.DATABASEUPLOAD: #N/A
Name _1B: #N/A
Name _1B00__10__.DATABASEUPLOAD: #N/A
Name _1C: #N/A
Name _1D: #N/A
Name _1E: #N/A
Name _1F: #N/A
Name _1G: #N/A
Name _1H: #N/A
Name _1I: #N/A
Name _1J: #N/A
Name _1K: #N/A
Name _1S: #N/A
Name _2: #N/A
Name _2000년_하반기_계획: [1]IS!$J$7:$J$35
Name _20B00__51__.DATABASEUPLOAD: #N/A
Name _20T1: #N/A
Name _20T2: #N/A
Name _20세기상사: [2]INDEX!#REF!
Name _21B00__57__.DATABASEUPLOAD: #N/A
Name _22B00__6__.DATABASEUPLOAD: #N/A
Name _23B00__60__.DATABASEUPLOAD: #N/A
Name _24B00__61__.DATABASEUPLOAD: #N/A
Name _25B00__62__.DATABASEUPLOAD: #N/A
Name _26B00__7__.DATABASEUPLOAD: #N/A
Name _27B00__8__.DATABASEUPLOAD: #N/A
Name _28B00__9__.DATABASEUPLOAD: #N/A

Sheet 기본입력사항
A1: 7210 부문감사인 그룹감사지침서의 기본입력사항
A3: 기본입력항목 | B3: 기본입력내용(국문) | C3: 기본입력내용(영문)
A4: 지배기업명 | B4: ABC주식회사 | C4: ABC Compony
A5: 지배기업 회계연도 개시일 | B5: 43101
A6: 지배기업 회계연도 종료일 | B6: 43465
A7: 부문감사인명 | B7: XX회계법인 | C7: XX accounting corporation
A8: 감사지침서일 | B8: 43342
A9: 부문명 | B9: 가나다주식회사 | C9: GANADA compony
A10: 부문 회계연도 개시일 | B10: 43101
A11: 부문 회계연도 종료일 | B11: 43465
A12: 해당부문 전체중요성(백만원) | B12: 400
A13: 해당부문 경미한왜곡표시사항에 대한 기준치(백만원) | B13: 5
A14: 후속사건검토요청일 | B14: 43524
A16: * 본 시트는 기본입력사항을 입력하는 시트로서 출력하여 조서화하는 시트가 아닙니다.

Sheet 7210
A6: 7410 부문감사인에 대한 그룹감사지침서
A8: 지배기업명 : | B8: =기본입력사항!B4 -> ABC주식회사
A9: 회계연도 : | B9: =TEXT(기본입력사항!B5,"yyyy년 m월 d일")&"부터 "&TEXT(기본입력사항!B6,"yyyy년 m월 d일")&"까지" -> 2018년 1월 1일부터 2018년 12월 31일까지
A12: =기본입력사항!B7 -> XX회계법인 | B12: 귀중
D13: =기본입력사항!B8 -> 43342
A14: 삼가 귀 감사인의 무궁한 번영을 기원합니다.
A16: ="당 법인은 "&B8&"와 그 종속기업 (이하 ‘그룹’)의 "&TEXT(기본입력사항!B6,"yyyy년 m월 d일")&"로 종료되는 회계연도의 별도재무제표 및 연결재무제표에 대한 회계감사를 수행하고 있습니다." -> 당 법인은 ABC주식회사와 그 종속기업 (이하 ‘그룹’)의 2018년 12월 31일로 종료되는 회계연도의 별도재무제표 및 연결재무제표에 대한 회계감사를 수행하고 있습니다.
A17: 당 법인은 그룹의 본 감사와 관련하여 주식회사등의외부감사에관한법률 제21조 2항 및 대한민국의 회계감사기준 600 문단 40과 41에 따라, 그룹의 재무제표에 중요하게 영향을 미치는 부문인 (부문명) (이하 ‘부문’)에 대하여 첨부된 그룹감사지침서를 준수하여 감사절차를 수행할 것을 귀 법인에 요청드립니다. 귀 법인이 감사한 부문의 재무제표는 그룹의 연결재무제표 작성에 이용될 것입니다.
A18: =TEXT(기본입력사항!B6,"yyyy년 m월 d일")&"로 종료하는 회계연도에 대한 지배기업과 그 종속기업에 대한 연결재무제표 감사를 위한 "&YEAR(기본입력사항!B6)&"회계연도 그룹감사지침서를 첨부하였습니다. 그룹감사지침서 내의 모든 사항과 요청자료 양식을 숙독하시기 바라며, 첨부된 제출기한을 준수하여 당 법인이 요청한 사항을 제출해 주시기 바랍니다." -> 2018년 12월 31일로 종료하는 회계연도에 대한 지배기업과 그 종속기업에 대한 연결재무제표 감사를 위한 2018회계연도 그룹감사지침서를 첨부하였습니다. 그룹감사지침서 내의 모든 사항과 요청자료 양식을 숙독하시기 바라며, 첨부된 제출기한을 준수하여 당 법인이 요청한 사항을 제출해 주시기 바랍니다.
A20: 다음과 같은 사항이 있는 경우 즉시 담당공인회계사에게 연락주십시오.
A21: 담당 공인회계사 | B21: 전화번호 | C21: 팩스 | D21: 이메일
A24: 주소
A26: ●그룹감사지침서 내용 중 의문사항이 있는 경우
A27: ●해결 불가능한 사유의 발생으로 인하여 첨부된 제출기한을 준수할 수 없는 경우
A28: ●감사와 관련된 구체적 절차에 대한 변경의 필요성이 있는 경우
A29: ●예상되는 회계, 재무보고 및 감사에 관한 유의적 사항, 중대한 내부통제 취약점 및 부정의 징후가 발견된 경우 등 그룹감사인의 주의를 요하는 사항이 발견된 경우
A30: ●그룹감사지침서에 언급된 독립성 고려사항에 대한 검토나 적절한 사전승인 없이 수행된 서비스가 있는 경우
A31: ●적정의견을 도출할 수 없는 상황이 발생한 경우
A32: 귀 법인의 협조에 감사드립니다. 문의사항이나 제안사항이 있으면 상기 명기된 담당자에게 즉시 연락주십시오.
C33: Y Y 회 계 법 인
C34: 대표이사
A36: 일반사항
A37: 본 그룹감사지침서가 적용되는 업무에 관한 일반사항은 다음과 같습니다.
A39: (1) 그룹에 관한 정보
A40: 그룹명 | B40: =기본입력사항!B4&"와 그 종속기업" -> ABC주식회사와 그 종속기업
A41: 그룹의 사업내용
A42: 특수관계자 목록
A46: (기타사항: 전기대비 사업의 주요 변동내역 등)
A51: (2) 귀 법인의 업무범위
A52: 부문명 | B52: =기본입력사항!B9 -> 가나다주식회사
A53: 재무보고체계 | B53: 선택(Y/N)
B54: Y/N | C54: 한국채택국제회계기준
B55: Y/N | C55: 일반기업회계기준
B56: Y/N | C56: 그룹회계정책
B57: Y/N | C57: 기타
A58: 회계감사기준 | B58: Y/N | C58: 대한민국의 회계감사기준
B59: Y/N | C59: 기타
A60: 대상 회계연도 | B60: =TEXT(기본입력사항!B10,"yyyy년 m월 d일")&"부터 "&TEXT(기본입력사항!B11,"yyyy년 m월 d일")&"까지" -> 2018년 1월 1일부터 2018년 12월 31일까지
A61: 업무유형 | B61: 감사 (*1)
A62: 상세 업무유형 | B62: 선택(Y/N)
...
