Workbook

Sheet 2023개정사항
A2: 공시사항 점검표 목차 | B2: 개정 전 | C2: 개정 후 | D2: 주요변경 이유 | E2: 시행일과 경과규정
A3: K-GAAP 제22장 ’법인세회계‘ 개정 '국제조세개혁 – 필라2 모범규칙' >> 공표 전 >> 공표되는 즉시 소급적용
A4: K-GAAP 제22장 ’법인세회계‘ 문단 22.2의3 신설 | C4: 이 장에서는 경제협력개발기구(OECD)가 발표한 필라2 모범규칙을 시행하기 위하여 확정된 세법(그 규칙에서 기술하는 적격소재국 추가세를 시행하는 세법 포함)에서 생기는 법인세에 적용한다. 이하, 이러한 세법과 그 세법에서 생기는 법인세를 각각 '필라2 법률', '필라2 법인세'라고 한다. 이 장의 요구사항에 대한 예외로, 필라2 법인세와 관련되는 이연법인세 자산 및 부채를 인식하지 아니하고 이에 대한 정보도 공시하지 아니한다. | D4: (배경) 2021년 12월, 경제협력개발기구(OECD)는 경제의 디지털화로 생기는 세금 문제 해결을 목표로 하는 필라2 모범규칙(Pillar Two Model Rules)을 발표하였음 ㅇ 우리나라에서도 이를 반영하는 ’국제조세조정에 관한 법률’이 2022년 말에 개정되어 글로벌 최저한세 제도가 2024년부터 시행될 예정임 ㅇ IASB는 제도 시행 전까지 관련 법인세 회계처리를 명확히 할 시간이 부족하다고 판단하고 2023년 5월에 IAS 12를 개정(‘International Tax Reform-Pillar Two Model Rules’)하여, - 필라2 법인세와 관련되는 이연법인세 인식·공시의 예외 규정을 마련하고 관련 정보를 공시하도록 하였음 ㅇ 일반기업회계기준 적용대상 중에도 추가세액 납부가 예상되는 기업이 있는 것으로 파악되어 일반기업회계기준 제22장 ‘법인세회계’도 개정이 필요함 | E4: 1 일반기업회계기준 개정(2023년, 국제조세개혁 - 필라2 모범규칙)에 따라 문단 22.2의3, 22.46의1, 22.62를 추가하였다. 문단 22.2의3과 22.62⑴의 개정 내용은 개정 내용이 공표되는 즉시 시행하고, 문단 22.46의1, 22.62⑵·⑶의 개정 내용은 2024년 1월 1일부터 시행한다. 2 문단 22.2의3과 22.62⑴의 개정 내용은 공표일이 속한 회계연도부터 일반기업회계기준 제5장 ‘회계정책, 회계추정의 변경 및 오류’에 따라 소급 적용하고, 문단 22.46의1, 22.62⑵·⑶의 개정 내용은 시행일 이후 최초로 시작되는 회계연도부터 적용한다.
A5: K-GAAP 제22장 ’법인세회계‘ 문단 22.62 신설 | C5: 필라2 법인세와 관련되는 다음 사항은 주석으로 기재한다. ⑴ 문단 22.2의3에 따라 이연법인세 자산․부채 인식 및 공시에 대한 예외 규정을 적용하였다는 사실 ⑵ 필라2 법인세와 관련되는 당기법인세비용(수익) ⑶ 특정 회계연도에 필라 2 법인세를 신뢰성 있게 추정할 수 없다고 판단하여 문단 22.46의1을 적용한 경우, 그 사실과 해당 세액을 신고·납부해야 하는 기간참조).
A6: K-GAAP 제2장 재무제표의 작성과 표시 I 개정 '- 부채의 유동·비유동 분류' >> 공표전 >>2024년 1월 1일 이후 최초로 시작되는 회계연도부터 적용, 조기적용가능
A7: K-GAAP 제2장 '재무제표의 작성과 표시 I' 문단 2.28 수정 | B7: 보고기간종료일과 재무제표가 사실상 확정된 날 사이에 발생한 다음과 같은 사건은 주석으로 기재한다. ⑴장기채무로의 차환(또는 만기연장) ⑵차입약정 위반의 해소 ⑶차입약정 위반을 해소할 수 있도록 보고기간종료일로부터 1년을 초과하는 유예기간을 획득 | C7: 보고기간종료일과 재무제표가 사실상 확정된 날 사이에 발생한 다음과 같은 사건은 주석으로 기재한다. ⑴ 유동으로 분류된 부채를 장기채무로 차환한 경우(또는 만기연장) ⑵ 장기차입약정 위반으로 유동으로 분류된 부채에서 해당 위반사항이 해소된 경우 ⑶ 장기차입약정 위반으로 유동으로 분류된 부채에서 해당 위반을 해소할 수 있도록 보고기간종료일로부터 1년을 초과하는 유예기간을 채권자로부터 획득한 경우 ⑷ 비유동으로 분류된 부채를 결제한 경우 | D7: (배경) 일반기업회계기준(이하 ‘일반기준‘) 제2장에 따라 부채를 유동·비유동으로 분류할 때, 부채의 결제를 연기할 수 있는 권리가 무엇인지 불명확하고 부채의 결제의 의미와 방식에 대한 규정이 모호하여 실무에 혼란이 있었고 K-IFRS의 최근 개정내용*과도 차이가 있으므로 개정을 검토함 | E7: 시행일 1 일반기업회계기준 개정(2023년, 부채의 유동·비유동 분류)에 따라 문단 2.22⑶, 2.25, 2.26, 2.28을 개정하고, 2.22의2, 2.22의3, 2.27의2, 2.28의2, 2.28의3, 2.28의4를 추가하였다. 이 개정 내용은 2024년 1월 1일부터 시행한다. 2 이 개정 내용은 시행일 이후 최초로 시작되는 회계연도부터 적용하되, 조기 적용할 수도 있다. 경과규정 3 이 개정 내용은 시행일 이후 최초로 시작되는 회계연도부터 일반기업회계기준 제5장 ‘회계정책, 회계추정의 변경 및 오류’에 따라 소급적용한다.
A8: K-GAAP 제2장 '재무제표의 작성과 표시 I' 문단 2.28의2 신설 | C8: 문단 2.22~2.27을 적용할 때, 차입 약정으로 인해 발생한 부채의 결제를 연기할 수 있는 기업의 권리가 보고기간종료일로부터 1년 이내에 약정사항을 준수하는지 여부에 좌우될 때, 기업이 그 부채를 비유동으로 분류하는 경우가 있을 수 있다(문단 2.22의3 참조). 이러한 상황에서 보고기간종료일로부터 1년 이내에 부채가 상환될 수 있는 위험을 재무제표이용자가 이해할 수 있도록 기업은 다음의 정보를 주석에 공시한다. ⑴ 약정사항에 관한 정보(약정사항의 성격 및 기업이 약정사항을 준수해야 하는 시점 포함)와 관련 부채의 장부금액. ⑵ 기업이 약정사항을 준수하기 어려울 수 있음을 나타내는 사실과 상황이 있다면 그 내용(예를 들어, 기업이 잠재적 위반을 피하거나 완화하기 위해 보고기간 중 또는 보고기간 후 조치를 취한 사실). 그러한 사실과 상황에는 보고기간종료일 현재 기업의 상황을 기초로 평가한다면 약정사항이 준수되지 않았을 것이라는 사실도 포함될 수 있다.
A9: K-GAAP 시행일 및 경과규정(2022.12.2.) 개정 '소규모비상장 지배기업의 비외감기업 연결제외' >> 의결 2022.12.2. >> 22년부터 시행~27년까지 효력
A10: K-GAAP 시행일 및 경과규정 개정 | D10: (제안이유) 소규모비상장 지배기업의 연결재무제표 작성 부담을 완화하기 위해 비외감기업을 연결재무제표 작성 시 제외할 수 있도록 일반기업회계기준 ‘시행일 및 경과규정’의 개정안을 붙임 내용으로 확정하여 발표하고자 함 | E10: 시행일 1 다음 중 어느 하나에 해당하지 않는 지배기업은 일반기업회계기준 연차개선(2018년) 중 문단 4.4. 4.8⑴, 8.35, 32.3의 개정 내용을 적용하지 아니할 수 있다. ⑴ ‘자본시장과 금융투자업에 관한 법률’에 따른 상장법인, 증권신고서 제출법인, 사업보고서 제출대상법인 ⑵ 제3장 ‘재무제표의 작성과 표시Ⅱ(금융업)’에서 정의하는 금융회사 ⑶ ‘주식회사 등의 외부감사에 관한 법률’에 따른 대형비상장주식회사 ⑷ 제4장 ‘연결재무제표’에서 정의하는 연결실체에 위의 ⑴~⑶의 기업이 포함된 경우의 지배기업 2 이 개정 내용은 2022년 12월 31일부터 시행하고, 시행일이 속하는 회계연도부터 적용하며, 2027년 12월 31일이 속하는 회계연도까지 효력이 있다. 경과규정 3 문단 1의 개정 내용을 적용할 때 ‘주식회사 등의 외부감사에 관한 법률’ 제4조 및 같은 법 시행령 제5조에 따른 외부감사 대상이 아닌 기업을 종속기업으로 보지 아니한다. 다만, 계약 등에 의하여 다음 회계연도 말까지 처분이 예정된 기업은 종속기업으로 보지 아니하며, 해외종속기업의 경우에는 국내종속기업에 대한 규모기준을 준용하며, 분할하거나 다른 회사와 합병하여 새로운 회사를 설립하거나 새로 설립된 회사로서 직전 회계연도의 재무상태표가 없는 경우에는 설립시점의 금액 등으로 규모기준을 준용한다.

Sheet 8400
D4: 공시사항점검표
A7: (본 공시사항점검표는 2023년 08월 25일 현재 유효한 회계기준에 따라 작성되었으며, 이후의 제/개정사항에 대해 추가로 검토하여야 함)
A10: 회 사 명 : | F10: 작성자 | G10: 일자 | H10: * 공시사항점검표 목차에서 해당되는 항목을 모두 선택한 후 아래의 "인쇄범위" 필터에서 "Y"를 선택하여 필터링 한후 출력합니다.
A12: 결 산 일 : | F12: 검토자 | G12: 일자
A17: ※ 작성요령 :
A18: 1. 검토사항에는 Y, N, N/A 중 해당 사항을 기재하며, Y"인 경우에는 비고란에 주석번호 기재
H20: 인쇄범위 | I20: 일련번호
A21: 1. 일반사항 | H21: =VLOOKUP(I21,'공시사항점검표 목차(2023)'!$K$11:$L$73,2,FALSE) -> #N/A | I21: 1
A22: 1.1 회사의 개요 | H22: =VLOOKUP(I22,'공시사항점검표 목차(2023)'!$K$11:$L$73,2,FALSE) -> #N/A | I22: 1.1
A23: 내 용 | E23: 참조기준 | F23: 검토 | G23: 비고 | H23: =VLOOKUP(I23,'공시사항점검표 목차(2023)'!$K$11:$L$73,2,FALSE) -> #N/A | I23: 1.1
A24: 1. 회사의 개황, 주요영업내용, 최근의 경영환경변화 | E24: 일반기준 실2.20 | H24: =VLOOKUP(I24,'공시사항점검표 목차(2023)'!$K$11:$L$73,2,FALSE) -> #N/A | I24: 1.1
B25: ⑴ | C25: 설립일자 | H25: =VLOOKUP(I25,'공시사항점검표 목차(2023)'!$K$11:$L$73,2,FALSE) -> #N/A | I25: 1.1
B26: ⑵ | C26: 상장일자 | H26: =VLOOKUP(I26,'공시사항점검표 목차(2023)'!$K$11:$L$73,2,FALSE) -> #N/A | I26: 1.1
B27: ⑶ | C27: 본사 및 공장소재지 | H27: =VLOOKUP(I27,'공시사항점검표 목차(2023)'!$K$11:$L$73,2,FALSE) -> #N/A | I27: 1.1
B28: ⑷ | C28: 주요영업내용 | H28: =VLOOKUP(I28,'공시사항점검표 목차(2023)'!$K$11:$L$73,2,FALSE) -> #N/A | I28: 1.1
B29: ⑸ | C29: 대표이사 | H29: =VLOOKUP(I29,'공시사항점검표 목차(2023)'!$K$11:$L$73,2,FALSE) -> #N/A | I29: 1.1
B30: ⑹ | C30: 주요주주 및 지분율 | H30: =VLOOKUP(I30,'공시사항점검표 목차(2023)'!$K$11:$L$73,2,FALSE) -> #N/A | I30: 1.1
B31: ⑺ | C31: 최근의 경영환경변화 | H31: =VLOOKUP(I31,'공시사항점검표 목차(2023)'!$K$11:$L$73,2,FALSE) -> #N/A | I31: 1.1
A32: 1.2 회사의 주요 회계처리방침 등의 내용 | H32: =VLOOKUP(I32,'공시사항점검표 목차(2023)'!$K$11:$L$73,2,FALSE) -> #N/A | I32: 1.2
A33: 내 용 | E33: 참조기준 | F33: 검토 | G33: 비고 | H33: =VLOOKUP(I33,'공시사항점검표 목차(2023)'!$K$11:$L$73,2,FALSE) -> #N/A | I33: 1.2
A34: `1. 재무제표 작성기준 및 유의적인 거래와 회계사건의 회계처리에 적용한 회계정책 | E34: 일반기준 2.82 | H34: =VLOOKUP(I34,'공시사항점검표 목차(2023)'!$K$11:$L$73,2,FALSE) -> #N/A | I34: 1.2
B35: ⑴ | C35: 재무제표의 작성기준 | H35: =VLOOKUP(I35,'공시사항점검표 목차(2023)'!$K$11:$L$73,2,FALSE) -> #N/A | I35: 1.2
B36: ⑵ | C36: 수익을 인식하기 위하여 적용한 회계정책(용역제공거래의 진행률의 결정방법을 포함한다) | E36: 일반기준 16.18 | H36: =VLOOKUP(I36,'공시사항점검표 목차(2023)'!$K$11:$L$73,2,FALSE) -> #N/A | I36: 1.2
B37: ⑶ | C37: 재고자산 평가와 재고조사방법 | E37: 일반기준 7.22 | H37: =VLOOKUP(I37,'공시사항점검표 목차(2023)'!$K$11:$L$73,2,FALSE) -> #N/A | I37: 1.2
C38: ㈎ | D38: 재고자산의 원가결정방법 | H38: =VLOOKUP(I38,'공시사항점검표 목차(2023)'!$K$11:$L$73,2,FALSE) -> #N/A | I38: 1.2
C39: ㈏ | D39: 재고자산을 총액으로 보고한 경우 그 내용 | H39: =VLOOKUP(I39,'공시사항점검표 목차(2023)'!$K$11:$L$73,2,FALSE) -> #N/A | I39: 1.2
C40: ㈐ | D40: 재고자산의 저가법 적용기준 및 평가내용 | H40: =VLOOKUP(I40,'공시사항점검표 목차(2023)'!$K$11:$L$73,2,FALSE) -> #N/A | I40: 1.2
C41: ㈑ | D41: 담보로 제공한 재고자산의 종류와 금액 | H41: =VLOOKUP(I41,'공시사항점검표 목차(2023)'!$K$11:$L$73,2,FALSE) -> #N/A | I41: 1.2
B42: ⑷ | C42: 유가증권 | E42: 일반기준 6.18 | H42: =VLOOKUP(I42,'공시사항점검표 목차(2023)'!$K$11:$L$73,2,FALSE) -> #N/A | I42: 1.2
C43: ㈎ | D43: 공정가치로 평가하는 주요 유가증권의 분류별로 공정가치 측정방법과 공정가치를 결정할 때 사용한 주요가정(예: 할인율, 중도상환율) 등 재무제표이용자가 공정가치로 측정된 회계정보를 이해하는데 유용한 정보 | H43: =VLOOKUP(I43,'공시사항점검표 목차(2023)'!$K$11:$L$73,2,FALSE) -> #N/A | I43: 1.2
C44: ㈏ | D44: 실현손익을 계산하기 위한 유가증권의 원가 결정 방법(예：개별법, 총평균법, 이동평균법 또는 다른 합리적인 방법） | E44: 일반기준 6.A24 | H44: =VLOOKUP(I44,'공시사항점검표 목차(2023)'!$K$11:$L$73,2,FALSE) -> #N/A | I44: 1.2
B45: ⑸ | C45: 유의적인 회계정책의 요약은 다음의 사항을 포함한다. | H45: =VLOOKUP(I45,'공시사항점검표 목차(2023)'!$K$11:$L$73,2,FALSE) -> #N/A | I45: 1.2
C46: ㈎ | D46: 재무제표를 작성하는데 사용한 측정속성 | E46: 일반기준 2.86 | H46: =VLOOKUP(I46,'공시사항점검표 목차(2023)'!$K$11:$L$73,2,FALSE) -> #N/A | I46: 1.2
C47: ㈏ | D47: 재무제표를 이해하는데 필요한 기타의 회계정책 | H47: =VLOOKUP(I47,'공시사항점검표 목차(2023)'!$K$11:$L$73,2,FALSE) -> #N/A | I47: 1.2
C48: ㈐ | D48: 재무제표에 영향을 미치는 회계정책 적용시 경영진이 내린 판단의 근거 | E48: 일반기준 2.87 | H48: =VLOOKUP(I48,'공시사항점검표 목차(2023)'!$K$11:$L$73,2,FALSE) -> #N/A | I48: 1.2
A49: 2. 재무상태표 관련 공시 | H49: =VLOOKUP(I49,'공시사항점검표 목차(2023)'!$K$11:$L$73,2,FALSE) -> #N/A | I49: 2
A50: 2.1 자산 | H50: =VLOOKUP(I50,'공시사항점검표 목차(2023)'!$K$11:$L$73,2,FALSE) -> #N/A | I50: 2
A51: 2.1.1 현금 및 장단기 금융상품 | H51: =VLOOKUP(I51,'공시사항점검표 목차(2023)'!$K$11:$L$73,2,FALSE) -> #N/A | I51: 2.1
A52: 내 용 | E52: 참조기준 | F52: 검토 | G52: 비고 | H52: =VLOOKUP(I52,'공시사항점검표 목차(2023)'!$K$11:$L$73,2,FALSE) -> #N/A | I52: 2.1.1
A53: 1. 사용이 제한된 예금 | E53: 일반기준 실2.20 | H53: =VLOOKUP(I53,'공시사항점검표 목차(2023)'!$K$11:$L$73,2,FALSE) -> #N/A | I53: 2.1.1
...

Sheet 공시사항점검표 목차(2023)
A2: 8400 공시사항점검표(일반기업회계기준)
A3: 목차
A5: 회사명 | H5: 작성자 | I5: 일자
A7: 결산일 | H7: 검토자 | I7: 일자
A9: * "해당여부"를 선택하고 "해당여부"가 "Y"인 경우 해당주석번호를 기재함 ** 해당주석번호는 회사제시 재무제표의 주석번호를 의미함 *** 2023년 추가사항 및 개정이 포함된 항목은 굵은글씨(파란색)로 표시되어 있음
A10: 내용 | G10: 해당 여부 | H10: 주석 번호 | I10: 담당자 | J10: 일련번호 | K10: 해당 일련번호 | L10: 해당여부
A11: 1 | B11: 일반사항 | J11: 1 | K11: =IF(G11="Y",J11,0) -> 0 | L11: =IF(K11=0,"해당없음","Y") -> 해당없음
B12: 1.1 | C12: 회사의 개요 | J12: 1.1 | K12: =IF(G12="Y",J12,0) -> 0 | L12: =IF(K12=0,"해당없음","Y") -> 해당없음
B13: 1.2 | C13: 회사의 주요 회계처리방침 등의 내용 | J13: 1.2 | K13: =IF(G13="Y",J13,0) -> 0 | L13: =IF(K13=0,"해당없음","Y") -> 해당없음
A14: 2 | B14: 재무상태표 관련 공시 | J14: 2 | K14: =IF(G14="Y",J14,0) -> 0 | L14: =IF(K14=0,"해당없음","Y") -> 해당없음
B15: 2.1 | C15: 자산 | J15: 2.1 | K15: =IF(G15="Y",J15,0) -> 0 | L15: =IF(K15=0,"해당없음","Y") -> 해당없음
C16: 2.1.1 | D16: 현금 및 장단기 금융상품 | J16: 2.1.1 | K16: =IF(G16="Y",J16,0) -> 0 | L16: =IF(K16=0,"해당없음","Y") -> 해당없음
C17: 2.1.2 | D17: 매출채권 등 | J17: 2.1.2 | K17: =IF(G17="Y",J17,0) -> 0 | L17: =IF(K17=0,"해당없음","Y") -> 해당없음
C18: 2.1.3 | D18: 재고자산 | J18: 2.1.3 | K18: =IF(G18="Y",J18,0) -> 0 | L18: =IF(K18=0,"해당없음","Y") -> 해당없음
C19: 2.1.4 | D19: 유가증권 | J19: 2.1.4 | K19: =IF(G19="Y",J19,0) -> 0 | L19: =IF(K19=0,"해당없음","Y") -> 해당없음
C20: 2.1.5 | D20: 지분법적용투자주식 | J20: 2.1.5 | K20: =IF(G20="Y",J20,0) -> 0 | L20: =IF(K20=0,"해당없음","Y") -> 해당없음
C21: 2.1.6 | D21: 조인트벤처투자 | J21: 2.1.6 | K21: =IF(G21="Y",J21,0) -> 0 | L21: =IF(K21=0,"해당없음","Y") -> 해당없음
C22: 2.1.7 | D22: 투자자산 | J22: 2.1.7 | K22: =IF(G22="Y",J22,0) -> 0 | L22: =IF(K22=0,"해당없음","Y") -> 해당없음
C23: 2.1.8 | D23: 유형자산 | J23: 2.1.8 | K23: =IF(G23="Y",J23,0) -> 0 | L23: =IF(K23=0,"해당없음","Y") -> 해당없음
C24: 2.1.9 | D24: 무형자산 | J24: 2.1.9 | K24: =IF(G24="Y",J24,0) -> 0 | L24: =IF(K24=0,"해당없음","Y") -> 해당없음
C25: 2.1.10 | D25: 자산공통 | J25: 2.1.10 | K25: =IF(G25="Y",J25,0) -> 0 | L25: =IF(K25=0,"해당없음","Y") -> 해당없음
B26: 2.2 | C26: 부채 | J26: 2.2 | K26: =IF(G26="Y",J26,0) -> 0 | L26: =IF(K26=0,"해당없음","Y") -> 해당없음
C27: 2.2.1 | D27: 사채와 차입금 | J27: 2.2.1 | K27: =IF(G27="Y",J27,0) -> 0 | L27: =IF(K27=0,"해당없음","Y") -> 해당없음
C28: 2.2.2 | D28: 복합금융상품 | J28: 2.2.2 | K28: =IF(G28="Y",J28,0) -> 0 | L28: =IF(K28=0,"해당없음","Y") -> 해당없음
C29: 2.2.3 | D29: 금융부채 | J29: 2.2.3 | K29: =IF(G29="Y",J29,0) -> 0 | L29: =IF(K29=0,"해당없음","Y") -> 해당없음
C30: 2.2.4 | D30: 퇴직급여충당부채 | J30: 2.2.4 | K30: =IF(G30="Y",J30,0) -> 0 | L30: =IF(K30=0,"해당없음","Y") -> 해당없음
B31: 2.3 | C31: 자산부채공통 | J31: 2.3 | K31: =IF(G31="Y",J31,0) -> 0 | L31: =IF(K31=0,"해당없음","Y") -> 해당없음
B32: 2.4 | C32: 채권채무조정 | J32: 2.4 | K32: =IF(G32="Y",J32,0) -> 0 | L32: =IF(K32=0,"해당없음","Y") -> 해당없음
B33: 2.5 | C33: 자본 | J33: 2.5 | K33: =IF(G33="Y",J33,0) -> 0 | L33: =IF(K33=0,"해당없음","Y") -> 해당없음
C34: 2.5.1 | D34: 자본 | J34: 2.5.1 | K34: =IF(G34="Y",J34,0) -> 0 | L34: =IF(K34=0,"해당없음","Y") -> 해당없음
C35: 2.5.2 | D35: 주식기준보상 | J35: 2.5.2 | K35: =IF(G35="Y",J35,0) -> 0 | L35: =IF(K35=0,"해당없음","Y") -> 해당없음
A36: 3 | B36: 손익계산서 관련 공시 | J36: 3 | K36: =IF(G36="Y",J36,0) -> 0 | L36: =IF(K36=0,"해당없음","Y") -> 해당없음
B37: 3.1 | C37: 매출 및 매출원가 | J37: 3.1 | K37: =IF(G37="Y",J37,0) -> 0 | L37: =IF(K37=0,"해당없음","Y") -> 해당없음
B38: 3.2 | C38: 판매비와관리비 | J38: 3.2 | K38: =IF(G38="Y",J38,0) -> 0 | L38: =IF(K38=0,"해당없음","Y") -> 해당없음
B39: 3.3 | C39: 부가가치 | J39: 3.3 | K39: =IF(G39="Y",J39,0) -> 0 | L39: =IF(K39=0,"해당없음","Y") -> 해당없음
B40: 3.4 | C40: 법인세 | J40: 3.4 | K40: =IF(G40="Y",J40,0) -> 0 | L40: =IF(K40=0,"해당없음","Y") -> 해당없음
B41: 3.5 | C41: 주당이익 | J41: 3.5 | K41: =IF(G41="Y",J41,0) -> 0 | L41: =IF(K41=0,"해당없음","Y") -> 해당없음
B42: 3.6 | C42: 포괄손익 | J42: 3.6 | K42: =IF(G42="Y",J42,0) -> 0 | L42: =IF(K42=0,"해당없음","Y") -> 해당없음
B43: 3.7 | C43: 중단사업 | J43: 3.7 | K43: =IF(G43="Y",J43,0) -> 0 | L43: =IF(K43=0,"해당없음","Y") -> 해당없음
A44: 4 | B44: 현금흐름표 관련 공시 | J44: 4 | K44: =IF(G44="Y",J44,0) -> 0 | L44: =IF(K44=0,"해당없음","Y") -> 해당없음
...
